Workbook

Sheet Sprints
B1: Relació d'sprints
B2: Sprint | C2: Data Inici | D2: Data Fi | E2: Temàtica | F2: Mòduls molt | G2: Mòduls poc | H2: Continguts | M2: Març 2025 | U2: Abril 2025 | AC2: Maig 2025
B3: 1 | C3: 45733 | D3: 45744 | E3: Explicacions SCRUM | F3: M4, M5 | G3: M1, M2, M3, M7 | H3: Definició d'objectius i planificació | M3: dl | N3: dm | O3: dc | P3: dj | Q3: dv | R3: ds | S3: dg | U3: dl | V3: dm | W3: dc | X3: dj | Y3: dv | Z3: ds | AA3: dg | AC3: dl | AD3: dm | AE3: dc | AF3: dj | AG3: dv | AH3: ds | AI3: dg
E4: Configuració de la base del sistema | H4: Planificació i muntatge de la xarxa (WAN, LAN, WIFI) | R4: 1 | S4: 2 | V4: 1 | W4: 2 | X4: 3 | Y4: 4 | Z4: 5 | AA4: 6 | AF4: 1 | AG4: 2 | AH4: 3 | AI4: 4
H5: SO: Controlador de domini, clients, rpi, pfsense) Instal·lar | M5: 3 | N5: 4 | O5: 5 | P5: 6 | Q5: 7 | R5: 8 | S5: 9 | U5: 7 | V5: 8 | W5: 9 | X5: 10 | Y5: 11 | Z5: 12 | AA5: 13 | AC5: 5 | AD5: 6 | AE5: 7 | AF5: 8 | AG5: 9 | AH5: 10 | AI5: 11
C6: 2 | H6: Serveis bàsics per a la xarxa (DHCP, DNS, SSH) | M6: 10 | N6: 11 | O6: 12 | P6: 13 | Q6: 14 | R6: 15 | S6: 16 | U6: 14 | V6: 15 | W6: 16 | X6: 17 | Y6: 18 | Z6: 19 | AA6: 20 | AC6: 12 | AD6: 13 | AE6: 14 | AF6: 15 | AG6: 16 | AH6: 17 | AI6: 18
B7: 2 | C7: 45747 | D7: 45758 | E7: Web | F7: M8, M4 I M6 | H7: Controladors de domini: Usuaris, grups i carpetes compartides | M7: 17 | N7: 18 | O7: 19 | P7: 20 | Q7: 21 | R7: 22 | S7: 23 | U7: 21 | V7: 22 | W7: 23 | X7: 24 | Y7: 25 | Z7: 26 | AA7: 27 | AC7: 19 | AD7: 20 | AE7: 21 | AF7: 22 | AG7: 23 | AH7: 24 | AI7: 25
E8: single sign on | H8: Integració usaris Linux / Windows | M8: 24 | N8: 25 | O8: 26 | P8: 27 | Q8: 28 | R8: 29 | S8: 30 | U8: 28 | V8: 29 | W8: 30 | AC8: 26 | AD8: 27 | AE8: 28 | AF8: 29 | AG8: 30 | AH8: 31
E9: Seguretat bàsica | H9: Política de backups, Backups(+ftp/scp/...), política i gestors de contrasenyes, antivirus local i server | M9: 31
C11: 2 | H11: CMS (web pública i botiga) + LMS + single sign on
B12: 3 | C12: 45769 | D12: 45777 | E12: Millores de la xarxa | F12: M6, M7 | G12: M4 | H12: Confgiuració del proxy
H13: Assegurar comunicacions dels servidors: Apache "avançat" (errors, headers, SSL, control d'entrada )+ FTP (per alimentar-lo), DNS secundari?
C15: 3 | H15: Backups + single sign on: afegir a les noves incorporacions
B16: 4 | C16: 45784 | D16: 45800 | E16: Assegurament de la xarxa | F16: M6, M7 | G16: M4 | H16: DMZ
H17: VPN
H18: Publicació de serveis NAT intern
H19: Backups
H20: Monitoratge intern i extern ?? Config notificacions?
C21: 3 | H21: Ampliacions
C23: 45796 | E23: Darrera verificació del projecte
C24: 45797 | E24: Lliurament documentació
C25: 45799 | E25: Port Aventura
C26: 23 a 27/05 | E26: Presentacions

Sheet Horaris
A1: ACTUAL
B2: SMX2A1 | I2: SMX2A2 | P2: SMX2B1
B3: Dilluns | C3: Dimarts | D3: Dimecres | E3: Dijous | F3: Divendres | I3: Dilluns | J3: Dimarts | K3: Dimecres | L3: Dijous | M3: Divendres | P3: Dilluns | Q3: Dimarts | R3: Dimecres | S3: Dijous | T3: Divendres
A4: 0.33333333 | B4: --- | C4: M7 R. Sánchez 023 | D4: M4 J. Ferrés 024 | E4: M7 R. Sánchez 023 | F4: SMX2A Tutoria J. Ferrés 024 | H4: 0.33333333 | I4: M7 O. López 023 | J4: M7 O. López 024 | K4: M7 O. López 026 | L4: M8 O. Aspas 024 | M4: SMX2A Tutoria J. Ferrés 024 | O4: 0.33333333 | P4: M6 P. Tomé 026 | Q4: M6 P. Tomé 026 | R4: M4 J. Costa 023 | S4: M7 O. López 026 | T4: SMX2B Tutoria O. López 026
A5: 0.375 | B5: --- | F5: M7 R. Sánchez 024 | H5: 0.375 | M5: M4 J. Ferrés 023 | O5: 0.375 | T5: M7 O. López 026
A6: 0.41666667 | B6: --- | C6: M4 J. Ferrés 023 | D6: M8 O. Aspas 024 | E6: M4 J. Ferrés 023 | H6: 0.41666667 | I6: M6 P. Tomé 023 | J6: M8 O. Aspas 024 | K6: M4 J. Ferrés 026 | L6: --- | O6: 0.41666667 | P6: M4 J. Costa 026 | Q6: --- | R6: M8 E. Gutierrez 023 | S6: M8 E. Gutierrez 026
A7: 0.47916667 | B7: M6 V. Martín 024 | F7: M8 O. Aspas 024 | H7: 0.47916667 | J7: M6 P. Tomé 024 | L7: --- | M7: M6 P. Tomé 023 | O7: 0.47916667 | Q7: --- | S7: M4 J. Costa 026 | T7: M8 E. Gutierrez 026
A8: 0.52083333 | B8: M8 O. Aspas 024 | C8: ProjecteFOL M. Monteagud 023 | D8: --- | E8: M6 V. Martín 023 | F8: M6 V. Martín 024 | H8: 0.52083333 | I8: M4 J. Ferrés 023 | J8: --- | K8: M8 O. Aspas 026 | L8: --- | O8: 0.52083333 | P8: SMX2B ProjecteFOL M. Monteagud 025 | Q8: --- | R8: M7 O. López 023
A9: 0.5625 | F9: V.martin | H9: 0.5625 | J9: --- | K9: M8 O. Aspas 026 | L9: --- | M9: ProjecteFOL M. Monteag | O9: 0.5625 | P9: --- | Q9: --- | S9: --- | T9: M6 P. Tomé 02
A11: PROPOSTA
B12: SMX2A1 | I12: SMX2A2 | P12: SMX2B1
B13: Dilluns | C13: Dimarts | D13: Dimecres | E13: Dijous | F13: Divendres | I13: Dilluns | J13: Dimarts | K13: Dimecres | L13: Dijous | M13: Divendres | P13: Dilluns | Q13: Dimarts | R13: Dimecres | S13: Dijous | T13: Divendres
A14: 0.33333333 | B14: --- | C14: M7 R. Sánchez 023 | D14: M7 O. López 026 | F14: SMX2A Tutoria J. Ferrés 024 | H14: 0.33333333 | I14: M6 P. Tomé 026 | J14: M6 P. Tomé 026 | K14: M4 J. Ferrés 024 | L14: M8 O. Aspas 024 | M14: SMX2A Tutoria J. Ferrés 024 | O14: 0.33333333 | P14: M7 O. López 023 | Q14: M7 O. López 024 | R14: M4 J. Costa 023 | S14: M7 O. López 026 | T14: SMX2B Tutoria O. López 026
A15: 0.375 | B15: --- | E15: Roger | F15: M7 R. Sánchez 024 | H15: 0.375 | M15: M4 J. Ferrés 023 | O15: 0.375 | T15: M7 O. López 026
A16: 0.41666667 | B16: --- | C16: M8 O. Aspas 024 | D16: M8 O. Aspas 024 | E16: ROGER | H16: 0.41666667 | I16: M6 P. Tomé 023 | J16: M4 J. Ferrés 023 | K16: M4 J. Ferrés 026 | L16: M4 J. Ferrés 023 | O16: 0.41666667 | P16: M4 J. Costa 026 | Q16: --- | R16: M8 E. Gutierrez 023 | S16: M8 E. Gutierrez 026
A17: 0.47916667 | B17: M6 V. Martín 024 | C17: M4 J. Ferrés 023 | E17: ProjecteFOL M. Monteagud 023 | F17: M8 O. Aspas 024 | H17: 0.47916667 | J17: M6 P. Tomé 024 | M17: M6 P. Tomé 023 | O17: 0.47916667 | Q17: --- | S17: M4 J. Costa 026 | T17: M8 E. Gutierrez 026
A18: 0.52083333 | B18: M8 O. Aspas 024 | D18: M8 O. Aspas 026 | E18: M6 V. Martín 023 | F18: M6 V. Martín 024 | H18: 0.52083333 | I18: M4 J. Ferrés 023 | J18: --- | L18: --- | O18: 0.52083333 | P18: SMX2B ProjecteFOL M. Monteagud 025 | Q18: --- | R18: M7 O. López 023
A19: 0.5625 | D19: M8 O. Aspas 026 | E19: M6 V. Martín 023 | F19: V.martin | H19: 0.5625 | J19: --- | L19: --- | M19: ProjecteFOL M. Monteag | O19: 0.5625 | P19: --- | Q19: --- | S19: --- | T19: M6 P. Tomé 02
A21: PROPOSTA2
B22: SMX2A1 | I22: SMX2A2 | P22: SMX2B1
B23: Dilluns | C23: Dimarts | D23: Dimecres | E23: Dijous | F23: Divendres | I23: Dilluns | J23: Dimarts | K23: Dimecres | L23: Dijous | M23: Divendres | P23: Dilluns | Q23: Dimarts | R23: Dimecres | S23: Dijous | T23: Divendres
A24: 0.33333333 | B24: --- | C24: M7 R. Sánchez 023 | D24: M7 O. López 023 | E24: ROGER 23 | F24: SMX2A Tutoria J. Ferrés 024 | H24: 0.33333333 | I24: M6 P. Tomé 024 | J24: M6 P. Tomé 024 | K24: M4 J. Ferrés 024 | L24: M8 O. Aspas 024 | M24: SMX2A Tutoria J. Ferrés 024 | O24: 0.33333333 | P24: M7 O. López 026 | Q24: M7 O. López 026 | R24: M4 J. Costa 026 | S24: M7 O. López 026 | T24: SMX2B Tutoria O. López 026
A25: 0.375 | B25: --- | E25: Roger 23 | F25: M7 R. Sánchez 023 | H25: 0.375 | M25: M4 J. Ferrés 024 | O25: 0.375 | T25: M7 O. López 026
A26: 0.41666667 | B26: --- | C26: M4 J. Ferrés 023 | D26: M4 J. Ferrés 023 | E26: M4 J. Ferrés 023 | H26: 0.41666667 | I26: M6 P. Tomé 024 | J26: M8 O. Aspas 024 | K26: M8 O. Aspas 024 | O26: 0.41666667 | P26: M4 J. Costa 026 | Q26: --- | R26: M8 E. Gutierrez 026 | S26: M8 E. Gutierrez 026
A27: 0.47916667 | B27: M6 V. Martín 23 | C27: M4 J. Ferrés 023 | F27: M8 O. Aspas 023 | H27: 0.47916667 | J27: M6 P. Tomé 024 | M27: M6 P. Tomé 024 | O27: 0.47916667 | Q27: --- | S27: M4 J. Costa 026 | T27: M8 E. Gutierrez 026
A28: 0.52083333 | B28: M4 J. Ferrés 023 | C28: ProjecteFOL 023 | E28: M6 V. Martín 023 | F28: M6 V. Martín 023 | H28: 0.52083333 | I28: M8 O. Aspas 024 | J28: --- | K28: M8 O. Aspas 024 | L28: --- | O28: 0.52083333 | P28: SMX2B ProjecteFOL 026 | Q28: --- | R28: M7 O. López 026
A29: 0.5625 | E29: M6 V. Martín 023 | F29: V.martin 23 | H29: 0.5625 | J29: --- | K29: M8 O. Aspas 024 | L29: --- | M29: ProjecteFOL 24 | O29: 0.5625 | P29: --- | Q29: --- | S29: --- | T29: M6 P. Tomé 026
P31: Horas | R31: Grups tutor | V31: A1 | W31: A2 | X31: B
O32: JOAN | P32: 13 | Q32: =P32*$P$42/$P$43 -> 3.0588235 | R32: =ROUND(Q32,0) -> 3 | V32: 4 | W32: 6 | X32: 6
O33: OSCAR | P33: 13 | Q33: =P33*$P$42/$P$43 -> 3.0588235 | R33: =ROUND(Q33,0) -> 3 | U33: assignados | V33: 6 | W33: 4 | X33: 6
O34: PAU | P34: 10 | Q34: =P34*$P$42/$P$43 -> 2.3529412 | R34: =ROUND(Q34,0) -> 2
O35: ASPAS | P35: 10 | Q35: =P35*$P$42/$P$43 -> 2.3529412 | R35: 2 | S35: x
O36: ROGER | P36: 6 | Q36: =P36*$P$42/$P$43 -> 1.4117647 | R36: =ROUND(Q36,0) -> 1 | S36: x
O37: JORDI | P37: 6 | Q37: =P37*$P$42/$P$43 -> 1.4117647 | R37: =ROUND(Q37,0) -> 1 | S37: x
O38: VANESA | P38: 5 | Q38: =P38*$P$42/$P$43 -> 1.1764706 | R38: =ROUND(Q38,0) -> 1
O39: EVA | P39: 5 | Q39: =P39*$P$42/$P$43 -> 1.1764706 | R39: =ROUND(Q39,0) -> 1
R40: =SUM(R31:R39) -> 14
O42: Grups Notificats | P42: 16
O43: Total horas | P43: =SUM(P32:P39) -> 68
A73: 8 | C73: JOAN | D73: PAU | E73: TUT | F73: JOAN | H73: 8 | I73: OSCAR | J73: GUARDIA | K73: JOAN | L73: TUT | M73: OSCAR | O73: CAPS | P73: Pau | Q73: Van | R73: David
...

Sheet Històries
H2: Històries
B3: Sprint | C3: Història | I3: Documentació relacionada
B4: 1 | C4: Per a organitzar l'empresa necessitem una xarxa local amb accés a Internet. De moment tenim 10 treballadors, un equip d'IT (vosaltres) i el gerent. Disposem de 2 raspberry pi, 1 mikrotik i suficients PC per al muntatge | I4: Mapa lògic, Disseny de la xarxa: Mínims per a ser apte Adreçament: Ip’s vàlides en entorn local, màscares i gateways adequats. Concordancia de les IP's del mapa lògic amb els fitxers de configuració dels serveis instal·lats dns, noms de hosts, etc. Taula o document explicatiu sobre l’adreçament de la LAN (assignació IP’s, màscara i gateway) per a tots els dispositius de xarxa que ho necessitin. Tant mitjançant una taula o al mateix plànol lògic. Justificació del disseny Connexió a Internet
B5: 1 | C5: Per a organitzar l'empresa necessitem una xarxa local amb accés a Internet. De moment tenim 10 treballadors, un equip d'IT (vosaltres) i el gerent. Disposem de 2 raspberry pi, 1 mikrotik i suficients PC per al muntatge | I5: Manual d'ús de la wifi per part dels usuari (mòbil, laptop) Manual d'instal·lació i de configuració de la wifi incloent com fer canvis (passwords, reservar IP...)
B6: 1 | C6: Necessitem una xarxa wifi per els treballadors itinerants (portàtils) i una altre per als mòbils | I6: Manuals de configuració i administració
B7: 1 | C7: La resta dels nostres treballadors no són informàtics i, per tant, necessitem que la configuració de xarxa funcioni correctament i sense que hagin de fer res. No volem haver de posar IP i coses estranyes MAI. | I7: Mapa físic-lògic (sense plànol) indicant quins equips són virtuals i quins físics
B8: 1 | C8: Físicament tenim 3 despatxos per als departaments RRHH i COMPTABILITAT i TIC i un CPD. Al CPD només hi ha racks no s'hi pot treballar allà a no ser que sigui una urgència. Heu de poder administrar els servidors remotament | I8: Justificació de les versions de sistema operatiu, preus, llicències.
B9: 1 | C9: Els departaments RRHH i COMPTABILITAT necessiten treballar amb Windows mentrés que IT ho farà amb Linux
B10: 2 | C10: Mireu la pestanya de material. Allà teniu els dispositius que podeu fer servir. Una de les Raspberry Pi ha de ser un dels servidors | I10: Controladors de domini: Usuaris, grups i carpetes compartides
B11: 2 | C11: Integració usuaris a equips client Linux / Windows | I11: Manual Integració usuaris a equips client Linux / Windows
A12: single sign on | B12: 2 | C12: Cal disposar d'un pla de contingència que inclogui les còpies de seguretat. Cal considerar al menys el model 3-2-1 per poder assegurar un retorn a l'activitat habitual en el menor temps possible. Cal pensar en tots els aspectes: dispositius de xarxa configurables, ordinadors d'usuaris, dades dels usuaris, configuració de serveis, bases de dades, fitxers del servei web, etc. També cal conscienciar els usuaris sobre la seguretat de les contrasenyes i de tota mena d'amenaces de malware. Cal posar les mesures de seguretat que permetin mitigar els atacs esmentats, tant a màquines client com a servidors. En tot moment s'ha de respectar la legalitat vigent, com a mínim les Lleis específiques LOPD-GDD, LSSI-CE i LPI. No cal oblidar la documentació que es va desenvolupant durant el projecte.
B13: 2 | C13: Necessitem un gestor de continguts web per a la implementació de la web de l’empresa client i la seva botiga online. Ha de ser accessible el servei des de Internet i la intranet. Les característiques haurien de cobrir les següents expectatives: Servei de bases de dades relacionals per gestionar les dades de les aplicacions web i gestors de continguts Necessitem que l'idioma estigui en català i l’anglès. Ha de ser visible de forma correcte amb mòbil o tablet. Hem de poder veure l'imatge i els colors corporatius de l'empresa. També volem que estigui sempre tot correctament actualitzat i securitzat. | I13: CMS. Web corporativa. Manual d'ús per part dels usuaris, manual d'instal·lació i de configuració Documentació de l'elecció d'aquest CMS en comparació amb altres existents. Pressupost el cost d'aquest software, si en té, hores d'instal·lació, manteniment., etc. Relacionar-ho amb el hardware en termes de eficiència, adaptat al servei que ha de donar. Requeriments necessaris a nivell de maquinari i pre-requisits. Integració dels diferents usuaris/perfils. Realització de proves de funcionament i memòria de totes les proves realitzades. Enquestes i fòrum dins del gestor. Traductor del contingut a l'anglès. S'ha de poder accedir a aquesta en anglès i que funcioni. Personalització amb l'Imatge i colors de l’empresa client. Documentació de les incidències i errors apareguts i les solucions aportades a aquestes en tot el procés. Mecanismes de seguretat proporcionats pel propi CMS i externs a ell. Tasques d'actualització i de còpies de seguretat del gestor de continguts.* Single sign on. * Aquest apartat pot no realitzar-se si és redundant amb la part de seguretat i còpies de seguretat genèriques.
A14: web | B14: 2 | C14: També haurem de disposar d'un LMS per a l’empresa client que serveixi d’espai per a fer consultes als seus treballadors i formació a aquests. Necessitarem tenir dos cursos: un de “funcionament de l’empresa” (amb documents sobre normes generals, consultes/forums com el calendari laboral de l’any següent o aportació d’idees de nous productes/negocis, etc.) i un altre curs de temàtica lliure (relacionada amb l’empresa) i complexitat similar a la de la web corporativa. Servei de bases de dades relacionals per gestionar les dades de les aplicacions web i gestors de continguts Necessitem que l'idioma estigui en català i anglès. Hem de poder veure l'imatge i els colors corporatius de l'empresa. També volem que estigui sempre tot correctament actualitzat i securitzat. | I14: LMS Web cursos corporatius. Manual d'ús per part dels usuaris, manual d'instal·lació i de configuració Documentació del perquè d'aquest LMS i comparativa amb altres existents, així com els problemes tècnics trobats. Pressupost el cost d'aquest software si en té, hores d'instal·lació, manteniment., etc. Relacionar-ho amb el hardware en termes de eficiència, adaptat al servei que ha de donar. Requeriments necessaris a nivell de maquinari i pre-requisits. Integració dels diferents usuaris/perfils. Incorporació d'un usuari per cada membre del grup del tipus administrador i un per cada company de la classe del tipus noAdministrador. Realització de proves de funcionament i memòria de totes les proves realitzades. Creació dels dos cursos demanats i els rols necessaris per gestionar-los. Documenta i justifica els rols emprats. Creació de contingut als cursos amb diferent tipus de recursos i activitats per al personal de l'empresa. Es valorarà tant per quantitat com per qualitat i estructura. Importa i exporta continguts en diferents formats. Comprovació que els diferents usuaris poden accedir-hi i visualitzar els continguts correctament. Verificar què pot veure cada tipus d'usuari afegit. Manipula i genera perfils personalitzats i diferenciats. Explicar i documentar les normes d'ús als usuaris, etc. Documenta el procés de modificació. Realitza informes d'accés i utilització del lloc. Activa i configura els mecanismes de seguretat proporcionats pel propi LMS i externs. Aplicar el single sign on. Realitza còpies de seguretat i restauracions. * * Aquest apartat pot no realitzar-se si és redundant amb la part de seguretat i còpies de seguretat genèriques. És a dir, que es contempli en un altre apartat.
B15: 3 | C15: Es vol fer assegurar la navegació dels usuaris: - No volem que els usuaris de la xarxa puguin navegar a pornografia, violència i pàgines malware, spyware, etc. - No es pot navegar en hores en que l'empresa estigui tancada (L'horari és de 08 a 14:30) exceptuant el personal de manteniment TIC 24/7 - Pel personal de manteniment 24/7 es farà una doble comprovació IP/usuari. - Volem poder veure estadístiques d'ús per usuari. - L'usuari/password, com a tot el projecte, serà amb single sign on. - Considera una navegació diferent per als usuaris de la wifi mòbil, és a dir la idea es que només puguin navegar per internet. No han de poder accedir a cap recurs intern els usuaris de la wifi mòbil; els usuari de la wifi portàtil podran accedir als recursos igual que ho fan desde els pc fixes - Personalitza els missatge d'error amb instruccions clares i amb l'estil i marca de l'empresa | I15: Manuals d'instal·lació, d'administració i d'ús.
B16: 3 | C16: Volem assegurar les comunicacions dels servidors de l'empresa: - Estableix els mecanismes de control i xifrat de totes les comunicacions. - Considera establir doble mecanisme de control: IP, usuari/password - Considera fer redundancia dels servidors o serveis - Considera establir entorns chroot on puguis | I16: Manuals d'instal·lació, d'administració i d'ús.
B17: 3 | C17: En tot moment hem de saber l'estat de tots els serveis de la xarxa i ens hem d'assabentar quan algun servei cau. Cal tenir en compte que poden caure els mateixos serveis o els dispositius de xarxa d'interconnexió i per tant caldria monitorització des de dintre i fora la xarxa local. També hem de pensar en la possibiltat que el monitor pugui caure. | I17: Manuals de configuració i monitoratge dels serveis
B18: 3 | C18: Cal continuar millorant el pla de contingència per les noves característiques i serveis que es vagin afegint. No cal oblidar la documentació que es va desenvolupant durant el projecte. | I18: Afegir nous Backups + single sign on: afegir a les noves incorporacions
B19: 3
B20: 4 | C20: La xarxa local ha d'estar separada de la xarxa dels serveis públics o accessibles des d'Internet. Això implicarà afegir més elements a la infrastructura de xarxa i reorganitzar alguns. | I20: Manual d'ús del proxy per part dels usuari, manual d'instal·lació i de configuració (com fer canvis al proxy)
B21: 4 | C21: Alguns dels treballadors són itinerants. Han de poder accedir als recursos de l'empresa de forma segura desde casa seva. Servidor gràfic d'administració remota des de casa, un en windows i un en linux. | I21: Manual d'ús per part dels usuaris, manual d'instal·lació i de configuració
B22: 4 | C22: Heu de poder resoldre incidències dels portàtils dels treballadors itinerants sense que hagin de venir al despatx | I22: Manual d'ús per part dels usuaris, manual d'instal·lació i de configuració
B23: 4 | C23: Cal continuar millorant el pla de contingència per les noves característiques i serveis que es vagin afegint. No cal oblidar la documentació que es va desenvolupant durant el projecte. | I23: Actualització del pla de contingència i backup
B24: 4 | C24: Es vol mantenir un inventari de tots els actius de la xarxa per poder gestionar correctament maquinari, programari i actualitzacions. | I24: Programari d'inventari d'equips, dispositius de xarxa i CPD
B25: 4 | C25: Es vol estalviar ample de banda en les actualitzacions de programari, tant en equips Linux com Windows. | I25: Servidors d'actualitzacions i repositoris ( APT Mirror)

Sheet Material
A1: LECTIVES | B1: =#REF! -> #REF! | C1: =GRUPS!E1 -> TUTOR | D1: =GRUPS!F1 -> AULA | E1: Adaptadors RJ45-USB | F1: switch Mikrotik | G1: switch Mikrotik AP | H1: Switch 5 ports | I1: Switch 8 ports | J1: Switch | K1: cable ethernet | L1: Raspberry Pi 4 | M1: Raspberry Pi 5 | N1: Lector SD | O1: Cable HDMI | P1: SD 32 GB | Q1: SD 64 GB | R1: cable usb-c | S1: Transformadors/endoll hub usb | T1: Grimpadores | U1: Connectors RJ45 | V1: Teclat | W1: Ratoli | X1: Regleta | Y1: USB WIFI
A2: 1 | B2: =GRUPS!C2 -> Esmeralda | C2: =GRUPS!E2 -> JOAN | D2: =GRUPS!F2 -> A2
B3: =GRUPS!C3 -> Fernandez
B4: =GRUPS!C4 -> Jurado Castillo
A5: 2 | B5: =GRUPS!C5 -> Álvarez Calvo | C5: =GRUPS!E5 -> OSCAR | D5: =GRUPS!F5 -> B1
B6: =GRUPS!C6 -> Borràs Martínez
B7: =GRUPS!C7 -> Igual Lopez
A8: 3 | B8: =GRUPS!C8 -> Balada Segura | C8: =GRUPS!E8 -> OSCAR | D8: =GRUPS!F8 -> B1
B9: =GRUPS!C9 -> Gisbert García
B10: =GRUPS!C10 -> Navarro
A11: 4 | B11: =GRUPS!C11 -> Barriere Rodríguez | C11: =GRUPS!E11 -> EVA | D11: =GRUPS!F11 -> B1
B12: =GRUPS!C12 -> Moré Puig
B13: =GRUPS!C13 -> Risco Ruiz
A14: 5 | B14: =GRUPS!C14 -> Capitán Barallobre | C14: =GRUPS!E14 -> JORDI | D14: =GRUPS!F14 -> B1
B15: =GRUPS!C15 -> López Calzada
B16: =GRUPS!C16 -> Barreto Madrid
A17: 6 | B17: =GRUPS!C17 -> CONTRERAS GARRIDO | C17: =GRUPS!E17 -> OSCAR | D17: =GRUPS!F17 -> B1
B18: =GRUPS!C18 -> Cruces Alejo
B19: =GRUPS!C19 -> Galindo Matías
B20: =GRUPS!C20 -> del Moral Prados
A21: 7 | B21: =GRUPS!C21 -> Ivaylov Georgiev | C21: =GRUPS!E20 -> PAU
B22: =GRUPS!C22 -> López Mañé
B23: =GRUPS!C23 -> García Sabola
A24: 8 | B24: =GRUPS!C24 -> Ouniss El Aalali | C24: =GRUPS!E23 -> ASPAS
B25: =GRUPS!C25 -> Montero Retamosa
B26: =GRUPS!C26 -> Jurado Rodriguez
A27: 9 | B27: =GRUPS!C27 -> Sanchez Tena | C27: =GRUPS!E26 -> JOAN
B28: =GRUPS!C28 -> Muñoz Peris
B29: =#REF! -> #REF!
A30: 10 | B30: =GRUPS!C29 -> Tiscar Guisado | C30: =#REF! -> #REF!
B31: =GRUPS!C30 -> Lara Vera
B32: =GRUPS!C31 -> Prados
A33: 11 | B33: =GRUPS!C32 -> Garcia Tomás | C33: =GRUPS!E32 -> OSCAR
B34: =GRUPS!C33 -> Mandret Ramos
B35: =GRUPS!C34 -> Souane Koma
A36: 12 | B36: =GRUPS!C35 -> Díaz Villarroel | C36: =GRUPS!E35 -> JOAN
B37: =GRUPS!C36 -> Sáez Solà
B38: =GRUPS!C37 -> Trullas Aranda
A39: 13 | B39: =GRUPS!C38 -> Ortiz | C39: =GRUPS!E38 -> ROGER
B40: =GRUPS!C39 -> Borruel
...

Sheet GRUPS
A1: GRUP | B1: Alumnes | E1: TUTOR | F1: AULA | G1: JOAN | H1: EVA | I1: PAU | J1: ASPAS | K1: OSCAR | L1: VANESA | M1: JORDI | N1: ROGER | Q1: DAVID i VANESA | R1: 4 | S1: 6 | U1: 24 | V1: =COUNTIF(#REF!,24) -> 0 | W1: =V1*3 -> 0
A2: 1 | B2: Alex | C2: Esmeralda | D2: A2 | E2: JOAN | F2: A2 | Q2: OSCAR I ROMÀ | R2: 3 | S2: 3 | U2: 26 | V2: =COUNTIF(#REF!,26) -> 0 | W2: =V2*3+1 -> 1
B3: Victor | C3: Fernandez | D3: A2 | Q3: JAVIER I ROGER | R3: 3* | S3: 3
B4: Héctor | C4: Jurado Castillo | D4: B1
A5: 2 | B5: Víctor | C5: Álvarez Calvo | D5: B1 | E5: OSCAR | F5: B1
B6: Jan | C6: Borràs Martínez | D6: B1
B7: Roc | C7: Igual Lopez | D7: A1
A8: 3 | B8: Bernat | C8: Balada Segura | D8: B1 | E8: OSCAR | F8: B1
B9: Victor | C9: Gisbert García | D9: B1 | P9: GRUPS | Q9: 17 | R9: =Q9*3 -> 51
B10: Pol | C10: Navarro | D10: A1
A11: 4 | B11: Adrian | C11: Barriere Rodríguez | D11: B1 | E11: EVA | F11: B1 | R11: HORES CLASSE | S11: MITJA | T11: ROUND | U11: MANUAL | V11: AGAFATS
B12: Roger | C12: Moré Puig | D12: B1 | P12: JOAN | R12: 13 | S12: =R12*$Q$9/$R$20 -> 3.25 | T12: =round(S12,0) -> 3 | U12: 3 | V12: =COUNTIF(#REF!,"JOAN") -> 0
B13: Víctor | C13: Risco Ruiz | D13: B1 | P13: DAVID | R13: 11 | S13: =R13*$Q$9/$R$20 -> 2.75 | T13: =round(S13,0) -> 3 | U13: 3 | V13: =COUNTIF(#REF!,"DAVID") -> 0
A14: 5 | B14: Miguel | C14: Capitán Barallobre | D14: B1 | E14: JORDI | F14: B1 | P14: VANESA | R14: 11 | S14: =R14*$Q$9/$R$20 -> 2.75 | T14: =round(S14,0) -> 3 | U14: 3 | V14: =COUNTIF(#REF!,"VANESA") -> 0
B15: Arnau | C15: López Calzada | D15: B1 | P15: PAU | R15: 10 | S15: =R15*$Q$9/$R$20 -> 2.5 | T15: =round(S15,0) -> 3 | U15: 2 | V15: =COUNTIF(#REF!,"PAU") -> 0
B16: Daniel | C16: Barreto Madrid | D16: A1 | P16: OSCAR | R16: 6 | S16: =R16*$Q$9/$R$20 -> 1.5 | T16: =round(S16,0) -> 2 | U16: 2 | V16: =COUNTIF(#REF!,"OSCAR") -> 0
A17: 6 | B17: XAVIER | C17: CONTRERAS GARRIDO | D17: B1 | E17: OSCAR | F17: B1 | P17: ROGER | R17: 6 | S17: =R17*$Q$9/$R$20 -> 1.5 | T17: =round(S17,0) -> 2 | U17: 2 | V17: =COUNTIF(#REF!,"ROGER") -> 0
B18: Iker | C18: Cruces Alejo | D18: B1 | P18: JAVIER | R18: 6 | S18: =R18*$Q$9/$R$20 -> 1.5 | T18: =round(S18,0) -> 2 | U18: 1 | V18: =COUNTIF(#REF!,"JAVIER") -> 0
B19: Hector | C19: Galindo Matías | D19: A2 | P19: ROMÀ | R19: 5 | S19: =R19*$Q$9/$R$20 -> 1.25 | T19: =round(S19,0) -> 1 | U19: 1 | V19: =COUNTIF(#REF!,"ROMÀ") -> 0
A20: 7 | B20: Lluís | C20: del Moral Prados | D20: A2 | E20: PAU | F20: A2 | Q20: Total hores | R20: =sum(R12:R19) -> 68 | T20: =SUM(T12:T19) -> 19 | U20: =SUM(U12:U19) -> 17 | V20: =SUM(V12:V19) -> 0
B21: Ivo | C21: Ivaylov Georgiev | D21: A2
B22: Aaron | C22: López Mañé | D22: A2
A23: 8 | B23: Izan | C23: García Sabola | D23: A2 | E23: ASPAS | F23: A2
B24: Aya | C24: Ouniss El Aalali | D24: A2
B25: Marina | C25: Montero Retamosa | D25: A2
A26: 9 | B26: Eloy | C26: Jurado Rodriguez | D26: A2 | E26: JOAN | F26: A2
B27: Marc | C27: Sanchez Tena | D27: B1
B28: Eric | C28: Muñoz Peris | D28: A2
A29: 10 | B29: Marc | C29: Tiscar Guisado | D29: B1 | E29: PAU | F29: A2
B30: Erik | C30: Lara Vera | D30: B1
B31: Joel | C31: Prados | D31: A2
A32: 11 | B32: Abel | C32: Garcia Tomás | D32: B1 | E32: OSCAR | F32: B1
B33: Gerard | C33: Mandret Ramos | D33: B1
B34: Mohamed | C34: Souane Koma | D34: A2
A35: 12 | B35: Izan | C35: Díaz Villarroel | D35: A1 | E35: JOAN | F35: A1
B36: Eric | C36: Sáez Solà | D36: A1
B37: Joel | C37: Trullas Aranda | D37: A1
A38: 13 | B38: Amanda | C38: Ortiz | D38: A1 | E38: ROGER | F38: A1
B39: Amanda | C39: Borruel | D39: A1
B40: Miquel | C40: Turegano | D40: A1
...

Sheet kit
C1: MATÏ | D1: TARDA
B2: Adaptadores rj45-usb | C2: 4 | D2: 1 | I2: comprar | J2: impresora | K2: 2
B3: Mikrotik AP | C3: 1 | D3: 1 | J3: post-it
B4: Mikortik | D4: 1 | J4: reducir enunciados
B5: rpi | C5: 1 | D5: 1 | J5: Ocultar rúbricas
B6: cables USB | C6: 1 | D6: 1
B7: cable HDMI | C7: 1 | D7: 1
B8: Font | C8: 1 | D8: 1
B9: Hub USB | D9: 1
B10: SD | C10: 1 | D10: 1
B11: Lector | C11: 1
B12: rj45 | C12: 6 | D12: 6
B13: ladrón | C13: 1 | D13: 1
B14: adaptadors USB-C RJ45 | D14: 3 | E14: Jordi proveeix

Sheet Enllaços
B1: Enunciat
B2: Descripció | C2: Enllaç
B3: Enunciat | C3: https://docs.google.com/document/d/1xAeB1yeXMUAWvmYFU2Mi_8Du_9ju_sLUHI085oX0rkI/edit
B6: Scrum
B7: Descripció | C7: Enllaç
B8: Diapos (en 5 minuts) | C8: https://prezi.com/yb2uleyhubl7/scrum-en-5-minutos/
B9: Vídeo (en 10 minuts) | C9: https://www.youtube.com/watch?v=PlLHc60egiQ
B10: Curs online | C10: https://www.youtube.com/watch?v=qRx8BkjY8lY&list=PLCdd5nLIOVnZKY4afaLSXwmTOBkdwOGzo
B11: Silicon Valley | C11: https://www.youtube.com/watch?v=oyVksFviJVE
C12: https://www.youtube.com/watch?v=o0Xo-BbgIL8
B13: Planning Poker | C13: https://planningpokeronline.com/
B15: Elevator Pitch
B16: Descripció | C16: Enllaç
B18: - Vídeo: Què és elevator pitch (Fundació la caixa): | C18: https://www.youtube.com/watch?v=2b3xG_YjgvI
B19: - Com fer un pitch: | C19: https://www.youtube.com/watch?v=554Fwv7jQMI
B20: - Diapositives sobre elevator pitch (mtodologia): | C20: https://www.slideshare.net/jordipuigdellivol/elevator-pitch-8033336
B21: - Curs complet sobre elevator pitch: | C21: http://www.myelevatorpitch.es/videos-del-curso/video-1.html
B22: - Prezi, com presentar un elevator pitch: | C22: https://prezi.com/cchk1p7xhs_2/como-presentar-un-elevator-pitch/
B26: Petxa Kutxa
B27: Descripció | C27: Enllaç
B28: Què és? | C28: https://www.socialmediaycontenidos.com/que-es-pecha-kucha-el-metodo-infalible-para-presentaciones-eficaces/
B32: Diagrames i mapa lògic
B33: Descripció | C33: Enllaç
B34: Diagrames integrat amb Drive | C34: https://draw.io
B35: Diagrames | C35: https://apps.nulab.com/signin

Sheet Aules
A1: GRUP | B1: Alumnes | E1: TUTOR | F1: AULA | G1: AULA | H1: Joan | I1: Pau | J1: Vanesa | K1: Eva | L1: Aspas | M1: Jordi | N1: Roger | S1: DAVID i VANESA | T1: 4 | U1: 6 | W1: 24 | X1: =COUNTIF(#REF!,24) -> 0 | Y1: =X1*3 -> 0
A2: 1 | B2: Alex | C2: Esmeralda | D2: A2 | F2: B | G2: x | H2: - | I2: x | S2: OSCAR I ROMÀ | T2: 3 | U2: 3 | W2: 26 | X2: =COUNTIF(#REF!,26) -> 0 | Y2: =X2*3+1 -> 1
B3: Victor | C3: Fernandez | D3: A2 | S3: JAVIER I ROGER | T3: 3* | U3: 3
B4: Héctor | C4: Jurado Castillo | D4: B1
A5: 2 | B5: Víctor | C5: Álvarez Calvo | D5: B1 | F5: B | G5: x | I5: x | K5: x | M5: x
B6: Jan | C6: Borràs Martínez | D6: B1
B7: Roc | C7: Igual Lopez | D7: A1 | O7: B | P7: Oscar
A8: 3 | B8: Bernat | C8: Balada Segura | D8: B1 | F8: B | G8: x | I8: x | K8: x | M8: x | P8: Jordi
B9: Victor | C9: Gisbert García | D9: B1 | P9: Eva | R9: GRUPS | S9: 17 | T9: =S9*3 -> 51
B10: Pol | C10: Navarro | D10: A1 | P10: Pau
A11: 4 | B11: Adrian | C11: Barriere Rodríguez | D11: B1 | F11: B | G11: x | I11: x | K11: x | M11: x | T11: HORES CLASSE | U11: MITJA | V11: ROUND | W11: MANUAL | X11: AGAFATS
B12: Roger | C12: Moré Puig | D12: B1 | R12: JOAN | T12: 13 | U12: =T12*$S$9/$T$27 -> 3.25 | V12: =round(U12,0) -> 3 | W12: 3 | X12: =COUNTIF(#REF!,"JOAN") -> 0
B13: Víctor | C13: Risco Ruiz | D13: B1 | R13: DAVID | T13: 11 | U13: =T13*$S$9/$T$27 -> 2.75 | V13: =round(U13,0) -> 3 | W13: 3 | X13: =COUNTIF(#REF!,"DAVID") -> 0
A14: 5 | B14: Miguel | C14: Capitán Barallobre | D14: B1 | F14: B | G14: x | I14: x | K14: x | M14: x | R14: VANESA | T14: 11 | U14: =T14*$S$9/$T$27 -> 2.75 | V14: =round(U14,0) -> 3 | W14: 3 | X14: =COUNTIF(#REF!,"VANESA") -> 0
B15: Arnau | C15: López Calzada | D15: B1 | R15: PAU | T15: 10 | U15: =T15*$S$9/$T$27 -> 2.5 | V15: =round(U15,0) -> 3 | W15: 2 | X15: =COUNTIF(#REF!,"PAU") -> 0
B16: Daniel | C16: Barreto Madrid | D16: A1 | R16: OSCAR | T16: 6 | U16: =T16*$S$9/$T$27 -> 1.5 | V16: =round(U16,0) -> 2 | W16: 2 | X16: =COUNTIF(#REF!,"OSCAR") -> 0
A17: 6 | B17: XAVIER | C17: CONTRERAS GARRIDO | D17: B1 | F17: B | G17: x | H17: - | I17: x | O17: A | P17: Joan | R17: ROGER | T17: 6 | U17: =T17*$S$9/$T$27 -> 1.5 | V17: =round(U17,0) -> 2 | W17: 2 | X17: =COUNTIF(#REF!,"ROGER") -> 0
B18: Iker | C18: Cruces Alejo | D18: B1 | P18: Roger | R18: JAVIER | T18: 6 | U18: =T18*$S$9/$T$27 -> 1.5 | V18: =round(U18,0) -> 2 | W18: 1 | X18: =COUNTIF(#REF!,"JAVIER") -> 0
B19: Hector | C19: Galindo Matías | D19: A2 | P19: Aspas | R19: ROMÀ | T19: 5 | U19: =T19*$S$9/$T$27 -> 1.25 | V19: =round(U19,0) -> 1 | W19: 1 | X19: =COUNTIF(#REF!,"ROMÀ") -> 0
A20: 7 | B20: Abel | C20: Garcia Tomás | D20: B1 | F20: B | G20: x | H20: - | I20: x | P20: Vanesa
B21: Gerard | C21: Mandret Ramos | D21: B1
B22: Mohamed | C22: Souane Koma | D22: A2
A23: 8 | B23: Alex | C23: Ortega Carmona | D23: A2 | E23: 4? | F23: B | G23: x | H23: - | I23: x
B24: Marc | C24: Tiscar Guisado | D24: B1
B25: Erik | C25: Lara Vera | D25: B1
B26: Joel | C26: Prados | D26: A2
A27: 9 | B27: Lluís | C27: del Moral Prados | D27: A2 | F27: A | G27: x | H27: x | I27: x | L27: x | S27: Total hores | T27: =sum(T12:T19) -> 68 | V27: =SUM(V12:V19) -> 19 | W27: =SUM(W12:W19) -> 17 | X27: =SUM(X12:X19) -> 0
B28: Ivo | C28: Ivaylov Georgiev | D28: A2
B29: Aaron | C29: López Mañé | D29: A2
A30: 10 | B30: Izan | C30: García Sabola | D30: A2 | F30: A | G30: x | H30: x | I30: x | L30: x
B31: Aya | C31: Ouniss El Aalali | D31: A2
B32: Marina | C32: Montero Retamosa | D32: A2
A33: 11 | B33: Eloy | C33: Jurado Rodriguez | D33: A2 | F33: A | G33: x | H33: - | I33: x
B34: Marc | C34: Sanchez Tena | D34: B1
B35: Eric | C35: Muñoz Peris | D35: A2
A36: 12 | B36: Izan | C36: Díaz Villarroel | D36: A1 | F36: A | H36: x | J36: x | N36: x
B37: Eric | C37: Sáez Solà | D37: A1
B38: Joel | C38: Trullas Aranda | D38: A1
A39: 13 | B39: Amanda | C39: Ortiz | D39: A1 | F39: A | H39: x
B40: Amanda | C40: Borruel | D40: A1 | J40: x | N40: x
...

Sheet Tribunals
D2: Divendres 23 | E2: Dilluns 26 | F2: Dimarts 27
C3: 8
C6: 9
C9: 10
C12: 0.47916667
C15: 0.52083333
C18: 0.5625
B22: Horaris

Sheet WorkFlow
A2: Backlog
A3: Product backlog | E3: Sprint Backlog
A4: 1 | B4: Definir històries | E4: 1 | F4: Definir històries
A5: 2 | B5: Dividir històries en tasques | E5: 2 | F5: ordenar les tasques per prioritat
A6: 3 | B6: ordenar les tasques per prioritat | E6: 3 | F6: Estimar temps per cada tasca
A7: 4 | B7: temporitzar les tasques: | E7: 4 | F7: Afegir al kanban a "TO-DO"
A10: Tasques
A11: Tasques: que apuntar al post-it | E11: Necessari per tancar una tasca
A12: 1 | B12: Nom de la tasca | E12: 1 | F12: Haver testejat la tasca
A13: 2 | B13: Temps estimat | E13: 2 | F13: Documentació generada
A14: 3 | B14: Persona responsable
A16: Planning Poker
A17: per cada tasca
A18: 1 | B18: Penses el valor estimat en hores de la tasca
A19: 2 | B19: A cegues: tothom mostra la carta amb l'estimació
A20: 2 | B20: El més prudent explica les seves raons
A21: 3 | B21: El més optimista explica les seves raons
A22: 4 | B22: S'arriba a consens o es torna al pas 1
A24: Scrum diari
A25: Contingut
A26: 1 | B26: Que has fet? Quina tasca?
A27: 1 | B27: Problemes: demanar ajuda. Aportar solucions
A28: 2 | B28: Temps estimat
A29: 3 | B29: Persona responsable
A32: Revisió sprint
A33: Passos | E33: Resultat sprint | N33: W
A34: 1 | B34: Elevator Pitch | E34: 1 | F34: Elevator Pitch
A35: 2 | B35: Revisió tècnica | C35: --> Mitjançant Rúbrica | E35: 2 | F35: Revisió tècnica
A36: 3 | B36: Revisió de Material | E36: 3 | F36: Documentació
A37: 4 | B37: Revisió de les aportacions dels membres + canvi de rols
A38: 5 | B38: Definició dels objectius del següent sprint

Sheet TaulaActivitats
A2: Tasques
A3: Tasca | B3: Descripció | H3: Criteris d‘avaluació
A4: Documentació i recerca d’informació | B4: L’objectiu de la documentació és tenir referència de com instal·lar, configurar, administrar i utilitzar els sistema informàtic i les seves aplicacions. S'ha de documentar tot allò necessari per assolir aquest objectiu. Han de constar les fonts d’informació utilitzades. (bibliografia i webgrafia) | H4: Comprovar que es compleixin tots els punts esmentats en la Descripció i estiguin inclosos en la documentació final. La documentació ha de complir uns mínims per ser APTE: Tenir una estructura coherent. Contenir índexs per ubicar ràpidament les seves parts. Que en el contingut apareguin tots els apartats esmentats en la documentació final. No contenir faltes ortogràfiques.
A5: Disseny de la xarxa | B5: Plànol lògic Taula o document explicatiu sobre l’adreçament de la LAN (assignació IP’s, màscara i gateway) per a tots els dispositius de xarxa que ho necessitin. Tant mitjançant una taula o al mateix plànol lògic. Justificació del disseny Connexió a Internet | H5: Disseny de la xarxa: Mínims per a ser apte Adreçament: Ip’s vàlides en entorn local, màscares i gateways adequats. Concordancia amb els fitxers de configuració dels serveis instal·lats dns, noms de hosts
A6: Serveis de xarxa o internet | B6: Caldrà implementar els elements següents: DHCP, DNS, FTP, servidor web, Proxy, sistema d'administració remot. Tots els serveis han de ser segurs i els usuaris integrats al servei de directori. Servei Web. Aquest servidor web estarà configurat per donar serveis als següents llocs virtuals associats a la mateixa adreça IP però amb un nom de host diferent per a cada lloc web: www.gleannmaith.local formacio.gleannmaith.local Servei DNS LOCAL que gestionarà el domini DNS “gleannmaith.local” a nivell intern (adreces locals), amb noms de host pels diferents serveis (ftp.gleannmaith.local, formacio.gleannmaith.local, etc.). A més, servirà de memòria cau (“catxé”) de peticions DNS. Només crearem hosts per equips sense adreça dinàmica. Servei de control remot per consola i en mode gràfic (només per a ordinadors clients) per poder administrar remotament el servidor. L'únic usuari de consola que s'hi podrà connectar serà l'usuari “remot” que ha de poder, en cas necessari, convertir-se en “root” o executar comandes de “root”. Servei DHCP, ja que les adreces dels equips dels espais de l’empresa seran dinàmiques i repartides entre els espais de treball de la manera que es cregui adient i fent servir la classe de xarxa que es necessiti. Servidor FTP públic per a administrar el servei web. No s’ha de poder escalar directoris, no s’ha de permetre iniciar sessió a l’administrador i s’ha de limitar l’accés al servidor per evitar abús dels usuaris o sobrecàrrega del servidor (limitar ample de banda, limitar nombre de connexions simultànies des de la mateixa ip, limitar el nombre de connexions totals des de qualsevol ip, etc.). Servidor proxy, per donar accés controlat a Internet als usuaris de la xarxa i alhora augmentar el rendiment. Els requeriments del servidor proxy són: Les restriccions s'aplicaran atenent als usuaris i grups (fent servir usuaris integrats en el servei de directori). Cal definir i aplicar una política d’ús d’Internet (restriccions per usuaris, grups, categories, horaris, etc.) Cal tenir un sistema d’estadístiques del servidor proxy. Cal que es generin automàticament les estadístiques cada nit. Cal vigilar amb la rotació dels fitxers de log (servei logrotate) del proxy, que fa desaparèixer els fitxers de log en 2 dies. Cal pensar en els backups de configuracions i fitxers de dades dels diferents serveis, de manera que es pugui traslladar fàcilment un servei d’un equip a un altre. | H6: - Els servidors han d’estar disponibles. Han de respondre a ping, dig, nslookup, telnet, etc. segons el servei a testejar. - S’ha de poder carregar pàgines web mitjançant el nom de domini. - Comprovar l’accés a webs prohibides des de diferents ip origen, en diferents horaris. - Comprovar resolució DNS amb Nslookup. - Accedir amb consola remota amb un usuari autoritzat i un que no. Des d’un equip autoritzat i no autoritzat. - Comprovar concessions DHCP. - Pujar i baixar fitxers al servidor FTP. Comprovar restriccions de comptes, tràfic, etc. - Comprovar hosts de domini a Internet. Totes les proves es trobaran detallades al joc de proves que s’adjuntarà.
A7: Gestor de continguts. | B7: Instal·la un gestor de continguts web per a la implementació de la web de l’empresa client. Ha de ser accessible el servei des de Internet i la intranet. Aconsellem Wordpress. Servei de bases de dades relacionals per gestionar les dades de les aplicacions web i gestors de continguts (opció Apache+PHP+MySQL+PHPMyAdmin). Característiques i personalització del CMS amb plantilla “responsive design” o adaptativa. Habilita enquestes i un fòrum dins del gestor. Inclou un mòdul que tradueixi el contingut a l'anglès i s'ha de poder accedir a aquesta en anglès i que funcioni. Modifica/configura la plantilla triada, que està desenvolupada amb CSS, per ajustar-la a la imatge corporativa de l’empresa. Documenta les incidències aparegudes i les solucions aportades a aquestes en tot el procés. Realitza tasques d'actualització del gestor de continguts.* | H7: Explicació de les característiques d'aquest CMS. Desenvolupa (usant el CMS instal·lat) una web amb un mínim de 5 “pàgines” amb contingut (les enquestes, traduccions a l’anglès, etc. es compten a part). Pista: una possible referència la podeu trobar a webs com: https://www.migestoriaonline.es https://www.rollingstones.com http://www.layoutdisseny.com http://www.sanfeliu-santildefons.org Documenta el procés d'instal·lació mínimament en termes de resultat i problemes tècnics del CMS. Documenta el procés de configuració implicit en les tasques demanades. Servei de bases de dades relacionals per gestionar les dades de l’aplicació web i gestor de continguts (opció Apache+PHP+MySQL+PHPMyAdmin). Característiques i personalització del CMS. Habilitar enquestes i un fòrum dins del gestor. Ha de tenir un mòdul que tradueixi el contingut a l'anglès i s'ha de poder accedir a aquesta en anglès i que funcioni. Incorpora la imatge de l’empresa client a la web desenvolupada amb el gestor de continguts. Documenta les incidències aparegudes i les solucions aportades a aquestes en tot el procés. Realitza tasques d'actualització i de còpies de seguretat del gestor de continguts.* * Aquest apartat pot no realitzar-se si és redundant amb la part de seguretat i còpies de seguretat genèriques.
A8: Configuració d’un LMS. | B8: Instal·la un LMS per a l’empresa client que serveixi d’espai per a fer consultes als seus treballadors i formació a aquests. Caldrà crear i administrar dos cursos: un de “funcionament de l’empresa” (amb documents sobre normes generals, consultes/forums com el calendari laboral de l’any següent o aportació d’idees de nous productes/negocis, etc.) i un altre curs de temàtica lliure (relacionada amb l’empresa) i complexitat similar a la de la web corporativa. Com a sistema LMS s’aconsella Moodle. Servei de bases de dades relacionals per gestionar les dades de les aplicacions web i gestors de continguts (opció Apache+PHP+MySQL+PHPMyAdmin).* Característiques i personalització del LMS. Activació i ús de funcionalitats. Fòrums. Consultes. Fes la versió en català i carrega un mòdul per traduir-la a l’anglès. Escull i/o modifica les plantilles o CSS per tenir una imatge corporativa igual a la web del gestor de continguts. Seguiment d'ús del LMS. Documenta les incidències aparegudes i les solucions aportades a aquestes en tot el procés. Realitza una còpia de seguretat i actualització del curs.* | H8: Documentar el perquè d'aquest LMS i comparativa amb altres existents. Documenta el procés d'instal·lació mínimament en termes de resultat i problemes tècnics del CMS. Documenta el procés de configuració. Explicació de les característiques d'aquest LMS. Incloure en el pressupost el cost d'aquest software si en té, hores d'instal·lació, manteniment., etc. Relacionar-ho amb el hardware en termes de eficiència, adaptat al servei que ha de donar. Funcionalitat i aportacions específiques dins del projecte. Identifica els requeriments necessaris. Realitza proves de funcionament. Tria d'un tema (o “plantilla”) adient per la imatge del projecte. Crea els dos cursos demanats i els rols necessaris per gestionar-los. Documenta i justifica els rols emprats. Crea contingut als cursos amb diferent tipus de recursos i activitats per al personal de la empresa. Es valorarà tant per quantitat com per qualitat. Importa i exporta continguts en diferents formats. Comprova que els usuaris poden accedir-hi i visualitzar els continguts correctament. Manipula i genera perfils personalitzats. Inclou en la memòria totes les proves realitzades. Es valorarà qualsevol extra ideat i dut a terme. Comprova la funcionalitat de les comunicacions mitjançant fòrums, consultes, entre d'altres. Fes una introducció als diferents mòduls i blocs i explica el perquè has triat aquest mòduls i no altres. Explicar les normes d'ús dels usuaris, etc. Realitzar les proves de funcionament: per exemple, que els alumnes del curs de “bricolatge” enviïn una foto de la seva construcció en una activitat del tipus “penjar un fitxer” o que els empleats votin quin dels calendaris laborals proposats per a l’any vinent prefereixen. Cerca i interpreta documentació tècnica en les llengües oficials i en les de més ús al sector. Documenta el procés de modificació. Realitza informes d'accés i utilització del lloc. Es valorarà la descripció i la capacitat de resoldre problemes. Activa i configura els mecanismes de seguretat proporcionats pel propi LMS. Realitza còpies de seguretat i restauracions. * * Aquest apartat pot no realitzar-se si és redundant amb la part de seguretat i còpies de seguretat genèriques. És a dir, que es contempli en un altre apartat.
A9: Còpia de seguretat | B9: Dissenyar i implementar un sistema de còpies de seguretat per recuperar amb seguretat i eficiència les dades i el sistema (HDD, disc USB, NAS, servidor extern, etc.). Cal tenir en compte: Quins tipus de dades es guardaran, la freqüència d’actualització i la freqüència de la còpia (pla de còpies). On es guardaran (còpies locals i remotes, suports físics). Com es farà la restauració o instal·lació de zero d’equips clients (que passa si un usuari encén un pc i no arrenca). Com es farà la restauració de servidors (que passa si el disc dur es crema, per exemple). Com i quan es guarda la configuració de servidors (algun servei ha perdut els fitxers de configuració) Com es guarden els fitxers dels llocs web (planes web, plantilles, fitxers pujats) i les BD d'aquests (BD de Joomla, Moodle…) Pensar què passaria si s’esborren els fitxers de la BD. Com i quan es guardaran les dades dels usuaris (fitxers ofimàtics guardats a carpetes personals, que són remotes). Com es guardaran les configuracions de routers i/o switch si existeixen. etc. | H9: -Comprovació del pla de backup per a cada tipus de dispositiu i tipus de dades dintre els servidors. - Execució d’un backup qualsevol, escollit aleatòriament, després d’haver destruït les dades.
A10: Servei de directori i compartir recursos en xarxa | B10: Els treballadors només han de tenir un únic nom d'usuari i contrasenya per accedir als equips i al Moodle. A més quan accedeixin a l'ordinador se'ls munta automàticament la seva carpeta personal, si és possible. | H10: 1- Provar la instal·lació correcta del servidor LDAP. Per fer-ho 1.a - Comprovar que els paquets estiguin instal·lats. sudo dpkg -l slapd ldap-utils 1.b - Comprovar que la configuració sigui correcta mitjançant la comanda sudo slaptest 1.c- Afegir un usuari: Per fer-ho, s’escriu un arxiu test.ldif amb el contingut #Substituir els valors sintesi i cat # pels dels seus dominis dn:uid=test,dc=sintesi,dc=cat objectclass: inetorgperson uid: test sn: test cn: test displayName: test userpassword: test01 Executar la comanda: ldapadd -D “cn=admin,dc=sintesi,dc=cat” -W -f test.ldif (on síntesi i cat, canviar-ho pel domini que ells creïn i demanarà la contrasenya de l’administrador) Comprovar la inserció: ldapsearch -D “cn=admin,dc=sintesi,dc=cat” -W -b “dc=sintesi,dc=cat” test 1.d Comprovar integració amb tots els serveis i sessió d’usuari. Per fer-ho s’ha d’accedir a tots els serveis amb l’usuari test/test01. 1.e Comprovar carpeta. S’ha d’iniciar una sessió d’usuari al client (Linux o Windows) amb test/test01. Veure que apareix la carpeta repositori a l’escriptori. Que afegeixin un arxiu al servidor en aquella carpeta i veure que apareix en la del client. Ho poden haver fet per SAMBA o NFS i muntant la carpeta en el fitxer /etc/fstab.
A11: Monitoratge de xarxa | B11: Monitoriza tots els serveis que es pugui (per exemple amb Nagios) | H11: Entrar a la pàgina d’administració del monitor i veure la informació proporcionada. Comprovar missatges de correu amb avisos.
A12: Configuració de Firewall amb DMZ | B12: Configurar la seguretat perimètrica de la xarxa i serveis. | H12: Fer escaneig de ports per veure si el firewall actua. Comprovar l’accés a la xarxa i ús dels serveis locals.
A13: Part d’ampliació | B13: Implementació de la part d’ampliació escollida per a cada grup. Cada proposta té els seus propis criteris | H13: Implementa els elements específics de l’enunciat proposat.
A14: Fase de proves | B14: Proves parcials del sistema durant el seguiment. Proves globals de validació del sistema al final del projecte.Part d’ampliació | H14: Definir proves genèriques de funcionament del sistema: Crear usuari nou i accedir amb aquest a tots els serveis. Iniciar sessió en escriptori Guardar arxius en carpeta mòbil Accedir a internet i aula virtual amb el nou usuari (accedir a curs). Accedir amb VPN des d’un client remot (en cas de l’ampliació). Destruir alguna part del sistema i restaurar.
A15: Presentació | B15: Preparació de la presentació oral davant la comissió d’avaluació del projecte (presentació tipus Powerpoint i assaig).

Sheet FAQ
A1: FAQ
A2: Tema | B2: problema | C2: Resposta
A3: adm remota | B3: Hi ha alternatives open source per admin remota? | C3: Reviseu: https://alternativeto.net/category/networking-and-admin/remote-desktop-access/?license=opensource
A4: certificats | B4: Instal·lar i configurar una CA autònoma en Windows Server | C4: Reviseu https://rdr-it.com/es/autoridad-de-certificacion-autonoma-de-windows-server-instalacion-y-configuracion/
A5: mikrotik | B5: Eines de configuració per Mikrotik | C5: easy config with generator tools. made for MikroTik RouterOS https://buananetpbun.github.io/
A6: mikrotik | B6: No puc resetejar el mikrotik. | C6: Reviseu: https://help.mikrotik.com/docs/display/ROS/Reset+Button https://www.youtube.com/@mikrotik Feu: System->Reset config
A7: mikrotik | B7: Flash de la memòria | C7: https://forum.mikrotik.com/viewtopic.php?t=196477
A8: mikrotik | B8: Bridging and Switching | C8: Reviseu: https://help.mikrotik.com/docs/display/ROS/Bridging+and+Switching
A9: mikrotik | B9: Firewall | C9: Reviseu: https://help.mikrotik.com/docs/display/ROS/Firewall+and+Quality+of+Service
A10: mikrotik | B10: Wireless | C10: Reviseu: https://help.mikrotik.com/docs/display/ROS/Wireless
A11: mikrotik | B11: Winbox | C11: Reviseu: https://help.mikrotik.com/docs/display/ROS/WinBox
A12: moodle | B12: Si poseu el domini i s'ha instal·lat amb IP | C12: S'ha de modificar al config,php del directori moodle Revisar el/els virtual host i el port.
A13: nagios | B13: No es detecta el servidor DHCP | C13: Dintre el servei que falla, configurar el servei, reconfigurar, monitorear, i a la comanda de test "check_dhp! -s IP-SERVER -u -i enp0s17" o sigui afegir -u. Revisar https://nagios-plugins.org/doc/man/check_dhcp.html
... A26: xarxa USB | B26: No es pot fer ping a màquines virtuals connectades amb interfície pont | C26: Descartar problemes de interfícies, cables eth, etc. configurant a les interfícies físiques IP's de la mateixa xarxa per fer ping entre màquines físiques connectades. Reiniciar Virtualbox i si no, la màquina física

Sheet Assistencia
A1: 4 | BB1: Proves finals | BC1: Documentació | BM1: Documentació
A2: 4 | J2: Sprint 1 | U2: Sprint 2 | AE2: Sprint 3 | AP2: Sprint 4
J3: 1 | O3: =J3+1 -> 2 | U3: =O3+1 -> 3 | Z3: =U3+1 -> 4 | AE3: =Z3+1 -> 5 | AK3: 6 | AQ3: 7 | AV3: =AQ3+1 -> 8 | BH3: =BB3+1 -> 1 | BN3: 45069 | BQ3: 45072 | BT3: 45073 | BW3: TRIBUNAL | BY3: Recu Pràctic
J4: V | L4: P | M4: V | N4: P | O4: P | P4: V | Q4: P | R4: V | S4: P | U4: P | V4: V | W4: P | X4: V | Y4: P | Z4: P | AA4: V | AB4: P | AC4: V | AD4: P | AE4: V | AF4: P | AG4: V | AH4: P | AI4: V | AJ4: P | AK4: P | AL4: V | AM4: P | AN4: V | AO4: P | AQ4: P | AR4: V | AS4: P | AT4: V | AU4: P | AV4: P | AW4: V | AX4: P | AY4: V | AZ4: P | BB4: P | BC4: V | BD4: P | BE4: V | BF4: P | BH4: P | BI4: V | BJ4: P | BK4: V | BL4: P | BM4: V | BP4: P | BR4: P
A5: GRUP | B5: Alumnes | D5: TUTOR | E5: AULA | F5: Fins avui | G5: Total assistència | H5: TOTAL | I5: ROL | J5: 45368 | K5: =J5+1 -> 45369 | L5: =K5+1 -> 45370 | M5: =L5+1 -> 45371 | N5: =M5+1 -> 45372 | O5: =J5+7 -> 45375 | P5: =O5+1 -> 45376 | Q5: =P5+1 -> 45377 | R5: =Q5+1 -> 45378 | S5: =R5+1 -> 45379 | T5: ROL | U5: =O5+7 -> 45382 | V5: =U5+1 -> 45383 | W5: =V5+1 -> 45384 | X5: =W5+1 -> 45385 | Y5: =X5+1 -> 45386 | Z5: =U5+7 -> 45389 | AA5: =Z5+1 -> 45390 | AB5: =AA5+1 -> 45391 | AC5: =AB5+1 -> 45392 | AD5: =AC5+1 -> 45393 | AE5: ROL | AF5: =AD5+3+7 -> 45403 | AG5: =AF5+1 -> 45404 | AH5: =AG5+1 -> 45405 | AI5: =AH5+1 -> 45406 | AJ5: =AI5+1 -> 45407 | AK5: =AF5+7 -> 45410 | AL5: =AK5+1 -> 45411 | AM5: =AL5+1 -> 45412 | AN5: =AM5+1 -> 45413 | AO5: =AN5+1 -> 45414 | AP5: ROL | AQ5: =AK5+7 -> 45417 | AR5: =AQ5+1 -> 45418 | AS5: =AR5+1 -> 45419 | AT5: =AS5+1 -> 45420 | AU5: =AT5+1 -> 45421 | AV5: =AQ5+7 -> 45424 | AW5: =AV5+1 -> 45425 | AX5: =AW5+1 -> 45426 | AY5: =AX5+1 -> 45427 | AZ5: =AY5+1 -> 45428 | BB5: =AV5+7 -> 45431 | BC5: =BB5+1 -> 45432 | BD5: =BC5+1 -> 45433 | BE5: =BD5+1 -> 45434 | BF5: =BE5+1 -> 45435 | BH5: =BB5+7 -> 45438 | BI5: =BH5+1 -> 45439 | BJ5: =BI5+1 -> 45440 | BK5: =BJ5+1 -> 45441 | BL5: =BK5+1 -> 45442 | BM5: =BH5 -> 45438 | BN5: Aula | BO5: Arribada | BP5: Presenta | BQ5: Aula | BR5: Arribada | BS5: Presenta | BT5: Aula | BU5: Arribada | BV5: Presenta | BW5: COMPOSICIÓ
E6: 23 | F6: =H6/$H$59 -> 0 | G6: =H6/$G$59 -> 0 | H6: =sum(J6:BM6) -> 0
E7: 23 | F7: =H7/$H$59 -> 0 | G7: =H7/$G$59 -> 0 | H7: =sum(J7:BM7) -> 0
E8: 23 | F8: =H8/$H$59 -> 1 | G8: =H8/$G$59 -> 0.0053191489 | H8: =sum(J8:BM8) -> 1 | J8: 1
E9: 23 | F9: =H9/$H$59 -> 0 | G9: =H9/$G$59 -> 0 | H9: =sum(J9:BM9) -> 0
E10: 23 | F10: =H10/$H$59 -> 0 | G10: =H10/$G$59 -> 0 | H10: =sum(J10:BM10) -> 0
E11: 23 | F11: =H11/$H$59 -> 0 | G11: =H11/$G$59 -> 0 | H11: =sum(J11:BM11) -> 0
E12: 23 | F12: =H12/$H$59 -> 0 | G12: =H12/$G$59 -> 0 | H12: =sum(J12:BM12) -> 0
E13: 23 | F13: =H13/$H$59 -> 0 | G13: =H13/$G$59 -> 0 | H13: =sum(J13:BM13) -> 0
E14: 23 | F14: =H14/$H$59 -> 0 | G14: =H14/$G$59 -> 0 | H14: =sum(J14:BM14) -> 0
E15: 23 | F15: =H15/$H$59 -> 0 | G15: =H15/$G$59 -> 0 | H15: =sum(J15:BM15) -> 0
E16: 23 | F16: =H16/$H$59 -> 0 | G16: =H16/$G$59 -> 0 | H16: =sum(J16:BM16) -> 0
E17: 23 | F17: =H17/$H$59 -> 0 | G17: =H17/$G$59 -> 0 | H17: =sum(J17:BM17) -> 0
E18: 24 | F18: =H18/$H$59 -> 0 | G18: =H18/$G$59 -> 0 | H18: =sum(J18:BM18) -> 0
E19: 24 | F19: =H19/$H$59 -> 0 | G19: =H19/$G$59 -> 0 | H19: =sum(J19:BM19) -> 0
E20: 24 | F20: =H20/$H$59 -> 0 | G20: =H20/$G$59 -> 0 | H20: =sum(J20:BM20) -> 0
... E57: 26 | F57: =H57/$H$59 -> 0 | G57: =H57/$G$59 -> 0 | H57: =sum(J57:BM57) -> 0
X58: calc
F59: =G59-H59 -> 187 | G59: =210-22 -> 188 | H59: =MAX(H4:H55) -> 1
G60: 33
G61: 48
G62: =G59+G60+61 -> 282

Sheet Seguiment
A1: 4 | BB1: Proves finals | BC1: Documentació | BM1: Documentació
A2: 4 | J2: Sprint 1 | U2: Sprint 2 | AE2: Sprint 3 | AP2: Sprint 4
J3: 1 | O3: =J3+1 -> 2 | U3: =O3+1 -> 3 | Z3: =U3+1 -> 4 | AE3: =Z3+1 -> 5 | AK3: 6 | AQ3: 7 | AV3: =AQ3+1 -> 8 | BH3: =BB3+1 -> 1 | BN3: 45069 | BQ3: 45072 | BT3: 45073 | BW3: TRIBUNAL | BY3: Recu Pràctic
J4: V | L4: P | M4: V | N4: P | O4: P | P4: V | Q4: P | R4: V | S4: P | U4: P | V4: V | W4: P | X4: V | Y4: P | Z4: P | AA4: V | AB4: P | AC4: V | AD4: P | AE4: V | AF4: P | AG4: V | AH4: P | AI4: V | AJ4: P | AK4: P | AL4: V | AM4: P | AN4: V | AO4: P | AQ4: P | AR4: V | AS4: P | AT4: V | AU4: P | AV4: P | AW4: V | AX4: P | AY4: V | AZ4: P | BB4: P | BC4: V | BD4: P | BE4: V | BF4: P | BH4: P | BI4: V | BJ4: P | BK4: V | BL4: P | BM4: V | BP4: P | BR4: P
A5: GRUP | B5: Alumnes | D5: TUTOR | E5: AULA | J5: 45368 | K5: =J5+1 -> 45369 | L5: =K5+1 -> 45370 | M5: =L5+1 -> 45371 | N5: =M5+1 -> 45372 | O5: =J5+7 -> 45375 | P5: =O5+1 -> 45376 | Q5: =P5+1 -> 45377 | R5: =Q5+1 -> 45378 | S5: =R5+1 -> 45379 | T5: ROL | U5: =O5+7 -> 45382 | V5: =U5+1 -> 45383 | W5: =V5+1 -> 45384 | X5: =W5+1 -> 45385 | Y5: =X5+1 -> 45386 | Z5: =U5+7 -> 45389 | AA5: =Z5+1 -> 45390 | AB5: =AA5+1 -> 45391 | AC5: =AB5+1 -> 45392 | AD5: =AC5+1 -> 45393 | AE5: ROL | AF5: =AD5+3+7 -> 45403 | AG5: =AF5+1 -> 45404 | AH5: =AG5+1 -> 45405 | AI5: =AH5+1 -> 45406 | AJ5: =AI5+1 -> 45407 | AK5: =AF5+7 -> 45410 | AL5: =AK5+1 -> 45411 | AM5: =AL5+1 -> 45412 | AN5: =AM5+1 -> 45413 | AO5: =AN5+1 -> 45414 | AP5: ROL | AQ5: =AK5+7 -> 45417 | AR5: =AQ5+1 -> 45418 | AS5: =AR5+1 -> 45419 | AT5: =AS5+1 -> 45420 | AU5: =AT5+1 -> 45421 | AV5: =AQ5+7 -> 45424 | AW5: =AV5+1 -> 45425 | AX5: =AW5+1 -> 45426 | AY5: =AX5+1 -> 45427 | AZ5: =AY5+1 -> 45428 | BB5: =AV5+7 -> 45431 | BC5: =BB5+1 -> 45432 | BD5: =BC5+1 -> 45433 | BE5: =BD5+1 -> 45434 | BF5: =BE5+1 -> 45435 | BH5: =BB5+7 -> 45438 | BI5: =BH5+1 -> 45439 | BJ5: =BI5+1 -> 45440 | BK5: =BJ5+1 -> 45441 | BL5: =BK5+1 -> 45442 | BM5: =BH5 -> 45438 | BN5: Aula | BO5: Arribada | BP5: Presenta | BQ5: Aula | BR5: Arribada | BS5: Presenta | BT5: Aula | BU5: Arribada | BV5: Presenta | BW5: COMPOSICIÓ
A6: =Aules!A2 -> 1 | B6: =Aules!B2 -> Alex | C6: =Aules!C2 -> Esmeralda | D6: =GRUPS!E2 -> JOAN | E6: =GRUPS!F2 -> A2 | F6: Repartiment tasques
B7: =Aules!B3 -> Victor | C7: =Aules!C3 -> Fernandez | F7: Execució tasques
B8: =Aules!B4 -> Héctor | C8: =Aules!C4 -> Jurado Castillo | F8: Altres
A9: =Aules!A5 -> 2 | B9: =Aules!B5 -> Víctor | C9: =Aules!C5 -> Álvarez Calvo | D9: =GRUPS!E5 -> OSCAR | E9: =GRUPS!F5 -> B1 | F9: Repartiment tasques
B10: =Aules!B6 -> Jan | C10: =Aules!C6 -> Borràs Martínez | F10: Execució tasques
B11: =Aules!B7 -> Roc | C11: =Aules!C7 -> Igual Lopez | F11: Altres
A12: =Aules!A8 -> 3 | B12: =Aules!B8 -> Bernat | C12: =Aules!C8 -> Balada Segura | D12: =GRUPS!E8 -> OSCAR | E12: =GRUPS!F8 -> B1 | F12: Repartiment tasques
B13: =Aules!B9 -> Victor | C13: =Aules!C9 -> Gisbert García | F13: Execució tasques
B14: =Aules!B10 -> Pol | C14: =Aules!C10 -> Navarro | F14: Altres
A15: =Aules!A11 -> 4 | B15: =Aules!B11 -> Adrian | C15: =Aules!C11 -> Barriere Rodríguez | D15: =GRUPS!E11 -> EVA | E15: =GRUPS!F11 -> B1 | F15: Repartiment tasques
B16: =Aules!B12 -> Roger | C16: =Aules!C12 -> Moré Puig | F16: Execució tasques
B17: =Aules!B13 -> Víctor | C17: =Aules!C13 -> Risco Ruiz | F17: Altres
A18: =Aules!A14 -> 5 | B18: =Aules!B14 -> Miguel | C18: =Aules!C14 -> Capitán Barallobre | D18: =GRUPS!E14 -> JORDI | E18: =GRUPS!F14 -> B1 | F18: Repartiment tasques
B19: =Aules!B15 -> Arnau | C19: =Aules!C15 -> López Calzada | F19: Execució tasques
B20: =Aules!B16 -> Daniel | C20: =Aules!C16 -> Barreto Madrid | F20: Altres
A21: =Aules!A17 -> 6 | B21: =Aules!B17 -> XAVIER | C21: =Aules!C17 -> CONTRERAS GARRIDO | D21: =GRUPS!E17 -> OSCAR | E21: =GRUPS!F17 -> B1 | F21: Repartiment tasques
B22: =Aules!B18 -> Iker | C22: =Aules!C18 -> Cruces Alejo | F22: Execució tasques
B23: =Aules!B19 -> Hector | C23: =Aules!C19 -> Galindo Matías | F23: Altres
A24: =Aules!A20 -> 7 | B24: =Aules!B20 -> Abel | C24: =Aules!C20 -> Garcia Tomás | D24: =GRUPS!E20 -> PAU | E24: =GRUPS!F20 -> A2 | F24: Repartiment tasques
B25: =Aules!B21 -> Gerard | C25: =Aules!C21 -> Mandret Ramos | F25: Execució tasques
B26: =Aules!B22 -> Mohamed | C26: =Aules!C22 -> Souane Koma | F26: Altres
A27: =Aules!A23 -> 8 | B27: =Aules!B23 -> Alex | C27: =Aules!C23 -> Ortega Carmona | D27: =GRUPS!E23 -> ASPAS | E27: =GRUPS!F23 -> A2 | F27: Repartiment tasques
B28: =Aules!B24 -> Marc | C28: =Aules!C24 -> Tiscar Guisado | F28: Execució tasques
B29: =Aules!B25 -> Erik | C29: =Aules!C25 -> Lara Vera | F29: Altres
B30: =Aules!B26 -> Joel | C30: =Aules!C26 -> Prados
A31: =Aules!A27 -> 9 | B31: =Aules!B27 -> Lluís | C31: =Aules!C27 -> del Moral Prados | D31: JOAN | E31: A2 | F31: Repartiment tasques
B32: =Aules!B28 -> Ivo | C32: =Aules!C28 -> Ivaylov Georgiev | F32: Execució tasques
B33: =Aules!B29 -> Aaron | C33: =Aules!C29 -> López Mañé | F33: Altres
A34: =Aules!A30 -> 10 | B34: =Aules!B30 -> Izan | C34: =Aules!C30 -> García Sabola | D34: =GRUPS!E29 -> PAU | E34: =GRUPS!F29 -> A2 | F34: Repartiment tasques
B35: =Aules!B31 -> Aya | C35: =Aules!C31 -> Ouniss El Aalali | F35: Execució tasques
B36: =Aules!B32 -> Marina | C36: =Aules!C32 -> Montero Retamosa | F36: Altres
A37: =Aules!A33 -> 11 | B37: =Aules!B33 -> Eloy | C37: =Aules!C33 -> Jurado Rodriguez | D37: =GRUPS!E32 -> OSCAR | E37: =GRUPS!F32 -> B1 | F37: Repartiment tasques
B38: =Aules!B34 -> Marc | C38: =Aules!C34 -> Sanchez Tena | F38: Execució tasques
B39: =Aules!B35 -> Eric | C39: =Aules!C35 -> Muñoz Peris | F39: Altres
A40: =Aules!A36 -> 12 | B40: =Aules!B36 -> Izan | C40: =Aules!C36 -> Díaz Villarroel | D40: =GRUPS!E35 -> JOAN | E40: =GRUPS!F35 -> A1 | F40: Repartiment tasques
...

Sheet inventari
A1: Aula | B1: 23 | D1: Data Revisió
A2: Responsable | B2: David Lizana
A4: Material i eines del projecte | H4: COMPRAR | J4: Fungibles | P4: Cessións
